<?xml version='1.0'?>

<robot name="uvc_robot" xmlns:xacro="http://www.ros.org/wiki/xacro">

  <xacro:include filename="$(find robot_description)/urdf/uvc_robot_gazebo.xacro" />
  <xacro:include filename="$(find robot_description)/urdf/materials.xacro" />

  <link name='base_link'>
    <origin xyz="0.0 0.0 0.010" rpy="0 0 0" />
    <inertial>
      <mass value="100.0" />
      <origin xyz="0.0 0 0" rpy=" 0 0 0" />
      <inertia
        ixx="3.5" ixy="0" ixz="0"
        iyy="3.5" iyz="0"
        izz="1.0" />
    </inertial>
    <collision name='collision'>
      <origin xyz="0 0 0.7" rpy=" 0 0 0" />
      <geometry>
        <!-- <mesh filename="file://$(find robot_description)/meshes/uvc_robot_mesh.dae" /> -->
        <box size="0.9 0.9 1.2" />
      </geometry>
    </collision>

    <visual name='base_link_visual'>
      <origin xyz="0 0 0.7" rpy=" 0 0 0" />
      <geometry>
        <!-- <mesh filename="file://$(find robot_description)/meshes/uvc_robot_mesh.dae" /> -->
        <box size="0.9 0.9 1.2" />
      </geometry>
    </visual>

    <collision name='caster1_collision'>
      <origin xyz="-0.4 0.3 0.04" rpy=" 0 0 0" />
      <geometry>
        <sphere radius="0.04" />
      </geometry>
      <surface>
        <friction>
          <ode>
            <mu>0</mu>
            <mu2>0</mu2>
            <slip1>1.0</slip1>
            <slip2>1.0</slip2>
          </ode>
        </friction>
      </surface>
    </collision>

    <visual name='caster1_visual'>
      <origin xyz="-0.4 0.3 0.04" rpy=" 0 0 0" />
      <geometry>
        <sphere radius="0.04" />
      </geometry>
    </visual>
    <collision name='caster2_collision'>
      <origin xyz="0.4 0.3 0.04" rpy=" 0 0 0" />
      <geometry>
        <sphere radius="0.04" />
      </geometry>
      <surface>
        <friction>
          <ode>
            <mu>0</mu>
            <mu2>0</mu2>
            <slip1>1.0</slip1>
            <slip2>1.0</slip2>
          </ode>
        </friction>
      </surface>
    </collision>

    <visual name='caster2_visual'>
      <origin xyz="0.4 0.3 0.04" rpy=" 0 0 0" />
      <geometry>
        <sphere radius="0.04" />
      </geometry>
    </visual>

    <collision name='caster3_collision'>
      <origin xyz="0.4 -0.3 0.04" rpy=" 0 0 0" />
      <geometry>
        <sphere radius="0.04" />
      </geometry>
      <surface>
        <friction>
          <ode>
            <mu>0</mu>
            <mu2>0</mu2>
            <slip1>1.0</slip1>
            <slip2>1.0</slip2>
          </ode>
        </friction>
      </surface>
    </collision>

    <visual name='caster3_visual'>
      <origin xyz="0.4 -0.3 0.04" rpy=" 0 0 0" />
      <geometry>
        <sphere radius="0.04" />
      </geometry>
    </visual>

    <collision name='caster4_collision'>
      <origin xyz="-0.4 -0.3 0.04" rpy=" 0 0 0" />
      <geometry>
        <sphere radius="0.04" />
      </geometry>
      <surface>
        <friction>
          <ode>
            <mu>0</mu>
            <mu2>0</mu2>
            <slip1>1.0</slip1>
            <slip2>1.0</slip2>
          </ode>
        </friction>
      </surface>
    </collision>

    <visual name='caster4_visual'>
      <origin xyz="-0.4 -0.3 0.04" rpy=" 0 0 0" />
      <geometry>
        <sphere radius="0.04" />
      </geometry>
    </visual>
  </link>

  <!-- wheels =============================================================  -->

  <link name="left_wheel">
    <collision name="collision">
      <origin xyz="0 0 0" rpy="0 1.5707 1.5707" />
      <geometry>
        <cylinder radius="0.0775" length="0.05" />
      </geometry>
    </collision>
    <friction>
      <ode>
        <mu>0.1</mu>
        <mu2>0.1</mu2>
      </ode>
    </friction>
    <visual name="left_wheel_visual">
      <origin xyz="0 0 0" rpy="0 1.5707 1.5707" />
      <geometry>
        <cylinder radius="0.0775" length="0.05" />
      </geometry>
    </visual>
    <inertial>
      <origin xyz="0 0 0" rpy="0 1.5707 1.5707" />
      <mass value="4" />
      <cylinder_inertia m="4" r="0.0775" h="0.05" />
      <inertia
        ixx="1.0" ixy="0.0" ixz="0.0"
        iyy="1.0" iyz="0.0"
        izz="1.0" />
    </inertial>
  </link>

  <link name="right_wheel">
    <collision name="collision">
      <origin xyz="0 0 0" rpy="0 1.5707 1.5707" />
      <geometry>
        <cylinder radius="0.0775" length="0.05" />
      </geometry>
    </collision>
    <friction>
      <ode>
        <mu>0.1</mu>
        <mu2>0.1</mu2>
      </ode>
    </friction>
    <visual name="right_wheel_visual">
      <origin xyz="0 0 0" rpy="0 1.5707 1.5707" />
      <geometry>
        <cylinder radius="0.0775" length="0.05" />
      </geometry>
    </visual>
    <inertial>
      <origin xyz="0 0 0" rpy="0 1.5707 1.5707" />
      <mass value="4" />
      <cylinder_inertia m="4" r="0.0775" h="0.05" />
      <inertia
        ixx="1.0" ixy="0.0" ixz="0.0"
        iyy="1.0" iyz="0.0"
        izz="1.0" />
    </inertial>
  </link>

  <joint type="continuous" name="left_wheel_hinge">
    <origin xyz="0.0 0.46 0.0775" rpy="0 0 0" />
    <child link="left_wheel" />
    <parent link="base_link" />
    <axis xyz="0 1 0" rpy="0 0 0" />
    <limit effort="100" velocity="100" />
    <joint_properties damping="0.0" friction="0.0" />
  </joint>

  <joint type="continuous" name="right_wheel_hinge">
    <origin xyz="0.0 -0.46 0.0775" rpy="0 0 0" />
    <child link="right_wheel" />
    <parent link="base_link" />
    <axis xyz="0 1 0" rpy="0 0 0" />
    <limit effort="100" velocity="100" />
    <joint_properties damping="0.0" friction="0.0" />
  </joint>


  <!-- camera_link ========================================================  -->
  <link name="camera_link">
    <collision>
      <origin xyz="0. 0.0 0.0" rpy="0 0 0" />
      <geometry>
        <box size="0.05 0.05 0.05" />
      </geometry>
    </collision>

    <visual>
      <origin xyz="0. 0.0 0.0" rpy="0 0 0" />
      <geometry>
        <box size="0.05 0.05 0.05" />
      </geometry>
      <material name="green" />
    </visual>
  </link>
  <joint name="camera_joint" type="fixed">
    <axis xyz="0 1 0" />
    <origin xyz="0.25 0 0.40" rpy="0 +0.2617993877991 0" />
    <parent link="base_link" />
    <child link="camera_link" />
  </joint>

  <!-- velodyne_laserscan =================================================  -->
  <link name="velodyne_laserscan">
    <visual>
      <origin xyz="0.0 0 0" rpy="0 0 0" />
      <geometry>
        <cylinder radius="0.15" length="0.20" />
      </geometry>
      <material name="Red">
        <color rgba="0.7 0.1 0.1 1" />
      </material>
    </visual>
    <collision>
      <origin xyz="0 0 0" rpy="0 0 0" />
      <geometry>
        <cylinder radius="0.15" length="0.20" />
      </geometry>
    </collision>
    <inertial>
      <mass value="0.1" />
      <origin xyz="0 0 0" rpy="0 0 0" />
      <inertia
        ixx="0.1" ixy="0" ixz="0"
        iyy="0.1" iyz="0"
        izz="0.1" />
    </inertial>
  </link>

  <joint name="velodyne_laserscan_joint" type="fixed">
    <axis xyz="0 1 0" />
    <origin xyz="0.0 0.0 1.5" rpy="0 0 0" />
    <parent link="base_link" />
    <child link="velodyne_laserscan" />
  </joint>

  <!-- imu ================================================================  -->
  <joint name="imu_link_joint" type="fixed">
    <parent link="base_link" />
    <child link="imu_link" />
    <origin xyz="-0.032 0 0.068" rpy="1.57079633 0 0" />
  </joint>

  <link name="imu_link" />

  <!-- usb_cam ============================================================  -->
  <link name="usb_cam">
    <visual>
      <origin xyz="0.0 0 0" rpy="0 0 0" />
      <geometry>
        <box size="0.05 0.05 0.05" />
        <!-- <cylinder radius="0.15" length="0.20" /> -->
      </geometry>
      <material name="Red">
        <color rgba="0.7 0.1 0.1 1" />
      </material>
    </visual>
    <collision>
      <origin xyz="0 0 0" rpy="0 0 0" />
      <geometry>
        <box size="0.05 0.05 0.05" />
        <!-- <cylinder radius="0.15" length="0.20" /> -->
      </geometry>
    </collision>
    <inertial>
      <mass value="0.1" />
      <origin xyz="0 0 0" rpy="0 0 0" />
      <inertia
        ixx="0.1" ixy="0" ixz="0"
        iyy="0.1" iyz="0"
        izz="0.1" />
    </inertial>
  </link>

  <joint name="usb_cam_joint" type="fixed">
    <parent link="base_link" />
    <child link="usb_cam" />
    <origin xyz="-0.51 0.0 1.0" rpy="0 0 ${pi}" />
  </joint>

</robot>